Workbook

Sheet Project Overview
A1: PROJECT PLAN — CNI Lost & Found Management System
A2: ระยะเวลา: 3 มิ.ย. – 1 ธ.ค. 2568 (182 วันปฏิทิน / 130 วันทำการ) | ไม่รวมวันเสาร์–อาทิตย์ | Client: CNI
A4: Phase | B4: ช่วงเวลา | C4: วันทำการ | D4: งานหลัก
A5: Kick-Off | B5: 3–5 มิ.ย. | C5: ='Detailed Task Plan'!F5 -> 3 | D5: Kick-Off Meeting, Project Charter
A6: Requirement | B6: 8–30 มิ.ย. | C6: ='Detailed Task Plan'!F7 -> 22 | D6: BRD, SRS, Use Case, ER Diagram, Data Flow Diagram
A7: Design | B7: 1 ก.ค. - 31 ก.ค. | C7: ='Detailed Task Plan'!F13 -> 24 | D7: Wireframe, Design System, Hi-fi Prototype, Sign-off
A8: Development | B8: 3 ส.ค. - 25 พ.ย. | C8: ='Detailed Task Plan'!F18 -> 83 | D8: 7 Modules + Dashboard + Design QA
A9: Testing | B9: 14 พ.ย. - 30 พ.ย. | C9: ='Detailed Task Plan'!F28 -> 69 | D9: Unit Test, Integration Test (RFID E2E), Performance & Security Test
A10: UAT | B10: 1 ธ.ค. –14 ธ.ค. | C10: ='Detailed Task Plan'!F32 -> 9 | D10: Usability Test, UAT กับ CNI Staff ทุก Role, Bug Fix, Sign-off
A11: Go-Live | B11: 15 ธ.ค. - 22 ม.ค. | C11: ='Detailed Task Plan'!F37 -> 30 | D11: User Manual, Video Training, อบรม, Deploy Production, Support 2 สัปดาห์
A13: MAN-DAY SUMMARY BY ROLE (วันทำการ ไม่รวม เสาร์–อาทิตย์)
A14: Role | B14: ชื่อย่อ | C14: Man-Days รวม | D14: Phase หลัก | E14: หน้าที่หลัก
A15: Project Manager | B15: PM | C15: ='Detailed Task Plan'!G44 -> 24 | D15: ทุก Phase | E15: บริหารโครงการ, ควบคุม Timeline/Scope/Risk, ประสานงาน CNI, Status Report
A16: Business Analyst | B16: BA | C16: ='Detailed Task Plan'!H44 -> 200 | D16: Req, Design, UAT, Go-Live | E16: Business Process Analysis, BRD, Acceptance Criteria, UAT Support
A17: System Analyst | B17: SA | C17: ='Detailed Task Plan'!I44 -> 135 | D17: Req, Design, Dev, UAT | E17: SRS, Use Case, ER Diagram, Data Model, ตอบ Dev เรื่อง Business Logic
A18: UX/UI Designer | B18: UX/UI | C18: ='Detailed Task Plan'!J44 -> 45 | D18: Design, Dev, UAT | E18: Wireframe, Design System, Hi-fi Prototype (Figma), UI Review ทุก Sprint, Usability Testing
A19: Developer | B19: Dev | C19: ='Detailed Task Plan'!K44 -> 184 | D19: Dev, Testing, Go-Live | E19: พัฒนาทุก Module (Frontend+Backend), RFID Integration, Unit Test, Deploy
A20: QA Engineer | B20: QA | C20: ='Detailed Task Plan'!L44 -> 89 | D20: Testing, UAT | E20: Test Case, Unit/Integration/Performance Test, Defect Management
A21: GRAND TOTAL MAN-DAYS | C21: =SUM(C15:C20) -> 677
A23: หมายเหตุ: Man-Day = จำนวนวันทำงานจริง (วันจันทร์–วันศุกร์เท่านั้น)

Sheet Gantt Chart
F2: มิถุนายน 69 | J2: กรกฎาคม 69 | N2: สิงหาคม 69 | R2: กันยายน 69 | V2: ตุลาคม 69 | Z2: พฤศจิกายน 69 | AD2: ธันวาคม 69 | AH2: มกราคม 70
A3: # | B3: Phase | C3: Task / งาน | D3: เริ่มต้น | E3: สิ้นสุด | F3: W1 | G3: W2 | H3: W3 | I3: W4 | J3: W1 | K3: W2 | L3: W3 | M3: W4 | N3: W1 | O3: W2 | P3: W3 | Q3: W4 | R3: W1 | S3: W2 | T3: W3 | U3: W4 | V3: W1 | W3: W2 | X3: W3 | Y3: W4 | Z3: W1 | AA3: W2 | AB3: W3 | AC3: W4 | AD3: W1 | AE3: W2 | AF3: W3 | AG3: W4 | AH3: W1 | AI3: W2 | AJ3: W3 | AK3: W4
A4: KICK-OFF
A5: 1 | B5: Kick-Off | C5: Kick-Off Meeting & Project Charter | D5: 46176 | E5: 46178
A6: REQUIREMENT
A7: 2 | B7: Requirement | C7: Business Process Workshop (As-Is / To-Be) | D7: 46181 | E7: 46185
A8: 3 | B8: Requirement | C8: สำรวจพื้นที่ห้างและ Infrastructure , RFID Reader | D8: 46181 | E8: 46182
A9: 4 | B9: Requirement | C9: จัดทำ Business Requirements Document (BRD) | D9: 46188 | E9: 46192
A10: 5 | B10: Requirement | C10: จัดทำ System Requirements Spec (SRS) + Use Case | D10: 46190 | E10: 46196
A11: 6 | B11: Requirement | C11: จัดทำ ER Diagram + Data Flow Diagram | D11: 46197 | E11: 46203
A12: DESIGN
A13: 7 | B13: Design | C13: Wireframe | D13: 46204 | E13: 46206
A14: 8 | B14: Design | C14: Design System (Color, Typography, Components) | D14: 46209 | E14: 46213
A15: 9 | B15: Design | C15: Hi-fi Prototype ทุกหน้า Responsive (PC/Tablet/Mobile) | D15: 46213 | E15: 46233
A16: 10 | B16: Design | C16: Requirement + Design Sign-off (CNI) | D16: 46234 | E16: 46234
A17: DEVELOPMENT
A18: 11 | B18: Development | C18: System Architecture + DB Schema Design | D18: 46237 | E18: 46239
A19: 12 | B19: Development | C19: Dev Environment + CI/CD + Staging Setup | D19: 46240 | E19: 46245
A20: 13 | B20: Development | C20: Module: Lost Report (Frontend + Backend API) | D20: 46246 | E20: 46255
A21: 14 | B21: Development | C21: Module: Found Report + RFID Integration | D21: 46258 | E21: 46269
A22: 15 | B22: Development | C22: Module: Search & Match (Rule-based Scoring) | D22: 46272 | E22: 46290
A23: 16 | B23: Development | C23: Module: Property Management + Status Flow | D23: 46293 | E23: 46297
A24: 17 | B24: Development | C24: Module: Report & Statistics + Export | D24: 46300 | E24: 46311
A25: 18 | B25: Development | C25: Module: Admin + Master Data + CRUD + RBAC | D25: 46314 | E25: 46339
A26: 19 | B26: Development | C26: Dashboard & Analytics (Hotspot Heatmap) | D26: 46342 | E26: 46351
A27: TESTING
A28: 21 | B28: Testing | C28: Unit Test | D28: 46340 | E28: 46351
A29: 22 | B29: Testing | C29: Integration Test (API + RFID End-to-End) | D29: 46270 | E29: 46351
A30: 23 | B30: Testing | C30: Performance & Security Test | D30: 46352 | E30: 46356
A31: UAT
A32: 25 | B32: UAT | C32: จัดทำ UAT Test Case + Scenario | D32: 46357 | E32: 46359
A33: 26 | B33: UAT | C33: UAT กับเจ้าหน้าที่ CNI (L&F Officer, Supervisor, Admin) | D33: 46360 | E33: 46360
A34: 27 | B34: UAT | C34: Bug Fix + Regression Test | D34: 46364 | E34: 46367
A35: 28 | B35: UAT | C35: UAT Sign-off | D35: 46370 | E35: 46370
A36: GO-LIVE
A37: 30 | B37: Go-Live | C37: จัดทำ User Manual ภาษาไทย (ทุก Role) | D37: 46371 | E37: 46374
A38: 31 | B38: Go-Live | C38: ส่งแผนการอบรม และแก้ไขหลังจากพิจารณา | D38: 46377 | E38: 46391
A39: 32 | B39: Go-Live | C39: บันทึก Video การอบรมการใช้งานระบบ | D39: 46391 | E39: 46391
A40: 33 | B40: Go-Live | C40: อบรมผู้ใช้งาน (L&F Officer, Supervisor, Admin) | D40: 46392 | E40: 46392
A41: 34 | B41: Go-Live | C41: Deploy Production + RFID Configuration | D41: 46393 | E41: 46395
...

Sheet Detailed Task Plan
A1: Detailed Task Plan — CNI Lost & Found System
A2: Work-Day / Manday = วันทำงานจริง (จันทร์–ศุกร์) | ไม่รวม เสาร์–อาทิตย์ | Testing เริ่มพร้อม Dev วันที่ 14 พ.ย.
A4: # | B4: Phase | C4: Task / งาน | D4: เริ่มต้น | E4: สิ้นสุด | F4: WD | G4: PM MD | H4: BA MD | I4: SA MD | J4: UX/UI MD | K4: Dev MD | L4: QA MD | M4: รวม MD | N4: Priority | O4: Status | P4: Dependencies | Q4: หมายเหตุ
A5: KICK-OFF | F5: =SUM(F6) -> 3 | M5: =SUM(M6) -> 9
A6: 1 | B6: Kick-Off | C6: Kick-Off Meeting & Project Charter | D6: 46176 | E6: 46178 | F6: =NETWORKDAYS(D6,E6) -> 3 | G6: 3 | H6: 3 | I6: 3 | J6: – | K6: – | L6: – | M6: =SUM(G6:L6) -> 9 | N6: High | O6: Not Started | P6: - | Q6: ชี้แจง TOR, Scope, Timeline, ผู้รับผิดชอบ, วาง Ground Rule
A7: REQUIREMENT | F7: =SUM(F8:F12) -> 22 | G7: =SUM(G8:G12) -> 2 | H7: =SUM(H8:H12) -> 11 | I7: =SUM(I8:I12) -> 13 | J7: =SUM(J8:J12) -> 0 | K7: =SUM(K8:K12) -> 0 | L7: =SUM(L8:L12) -> 0 | M7: =SUM(M8:M12) -> 26
A8: 2 | B8: Requirement | C8: Business Process Workshop (As-Is / To-Be) | D8: 46181 | E8: 46185 | F8: =NETWORKDAYS(D8,E8) -> 5 | G8: 1 | H8: 4 | I8: 2 | J8: – | K8: – | L8: – | M8: =SUM(G8:L8) -> 7 | N8: High | O8: Not Started | P8: Task 1 | Q8: BA นำ Workshop กับ CNI, จัดทำ Process Flow ทุก Module
A9: 3 | B9: Requirement | C9: สำรวจพื้นที่ห้างและ Infrastructure , RFID Reader | D9: 46181 | E9: 46182 | F9: =NETWORKDAYS(D9,E9) -> 2 | G9: – | H9: – | I9: 2 | J9: – | K9: – | L9: – | M9: =SUM(G9:L9) -> 2 | N9: High | O9: Not Started | P9: Task 1 | Q9: SA + HW ระบุ Reader Location, Network Point, Sticker Type
A10: 4 | B10: Requirement | C10: จัดทำ Business Requirements Document (BRD) | D10: 46188 | E10: 46192 | F10: =NETWORKDAYS(D10,E10) -> 5 | G10: 1 | H10: 5 | I10: 1 | J10: – | K10: – | L10: – | M10: =SUM(G10:L10) -> 7 | N10: High | O10: Not Started | P10: Task 2 | Q10: BA เป็น Owner, SA Review — ครอบคลุมทุก Feature ตาม TOR
A11: 5 | B11: Requirement | C11: จัดทำ System Requirements Spec (SRS) + Use Case | D11: 46190 | E11: 46196 | F11: =NETWORKDAYS(D11,E11) -> 5 | G11: – | H11: 1 | I11: 4 | J11: – | K11: – | L11: – | M11: =SUM(G11:L11) -> 5 | N11: High | O11: Not Started | P11: Task 4 | Q11: SA เป็น Owner, BA Validate — Use Case ทุก Actor
A12: 6 | B12: Requirement | C12: จัดทำ ER Diagram + Data Flow Diagram | D12: 46197 | E12: 46203 | F12: =NETWORKDAYS(D12,E12) -> 5 | G12: – | H12: 1 | I12: 4 | J12: – | K12: – | L12: – | M12: =SUM(G12:L12) -> 5 | N12: High | O12: Not Started | P12: Task 5 | Q12: SA ออกแบบ Data Model และ Flow ทั้งหมด
A13: DESIGN | F13: =SUM(F14:F17) -> 24 | G13: =SUM(G14:G17) -> 1 | H13: =SUM(H14:H17) -> 4 | I13: =SUM(I14:I17) -> 4 | J13: =SUM(J14:J17) -> 24 | K13: =SUM(K14:K17) -> 0 | L13: =SUM(L14:L17) -> 0 | M13: =SUM(M14:M17) -> 33
A14: 7 | B14: Design | C14: Wireframe | D14: 46204 | E14: 46206 | F14: =NETWORKDAYS(D14,E14) -> 3 | G14: – | H14: 3 | I14: 3 | J14: 3 | K14: – | L14: – | M14: =SUM(G14:L14) -> 9 | N14: High | O14: Not Started | P14: Task 4,5 | Q14: UX/UI ออกแบบ Flow + Layout — BA/SA Review ความถูกต้อง
A15: 8 | B15: Design | C15: Design System (Color, Typography, Components) | D15: 46209 | E15: 46213 | F15: =NETWORKDAYS(D15,E15) -> 5 | G15: – | H15: – | I15: – | J15: 5 | K15: – | L15: – | M15: =SUM(G15:L15) -> 5 | N15: High | O15: Not Started | P15: Task 7 | Q15: Design Tokens, Button, Form, Table, Badge, Icon Style Guide
A16: 9 | B16: Design | C16: Hi-fi Prototype ทุกหน้า Responsive (PC/Tablet/Mobile) | D16: 46213 | E16: 46233 | F16: =NETWORKDAYS(D16,E16) -> 15 | G16: – | H16: – | I16: – | J16: 15 | K16: – | L16: – | M16: =SUM(G16:L16) -> 15 | N16: Critical | O16: Not Started | P16: Task 7,8 | Q16: Figma Prototype Interactive — Dev ใช้เป็น Handoff
A17: 10 | B17: Design | C17: Requirement + Design Sign-off (CNI) | D17: 46234 | E17: 46234 | F17: =NETWORKDAYS(D17,E17) -> 1 | G17: 1 | H17: 1 | I17: 1 | J17: 1 | K17: – | L17: – | M17: =SUM(G17:L17) -> 4 | N17: Critical | O17: Not Started | P17: Task 6,9 | Q17: CNI ลงนาม BRD + SRS + Hi-fi Mockup ก่อนเริ่ม Dev
A18: DEVELOPMENT | F18: =SUM(F19:F27) -> 83 | G18: =SUM(G19:G27) -> 0 | H18: =SUM(H19:H27) -> 76 | I18: =SUM(I19:I27) -> 10 | J18: =SUM(J19:J27) -> 7 | K18: =SUM(K19:K27) -> 83 | L18: =SUM(L19:L27) -> 0 | M18: =SUM(M19:M27) -> 176
A19: 11 | B19: Development | C19: System Architecture + DB Schema Design | D19: 46237 | E19: 46239 | F19: =NETWORKDAYS(D19,E19) -> 3 | G19: – | H19: – | I19: 3 | J19: – | K19: =F19 -> 3 | L19: – | M19: =SUM(G19:L19) -> 6 | N19: Critical | O19: Not Started | P19: Task 10 | Q19: Tech Stack, DB Schema, API Spec, Server/Infra Requirement
A20: 12 | B20: Development | C20: Dev Environment + CI/CD + Staging Setup | D20: 46240 | E20: 46245 | F20: =NETWORKDAYS(D20,E20) -> 4 | G20: – | H20: – | I20: – | J20: – | K20: =F20 -> 4 | L20: – | M20: =SUM(G20:L20) -> 4 | N20: High | O20: Not Started | P20: Task 11 | Q20: Git Repo, Docker, Pipeline, Staging Server, RFID Middleware
A21: 13 | B21: Development | C21: Module: Lost Report (Frontend + Backend API) | D21: 46246 | E21: 46255 | F21: =NETWORKDAYS(D21,E21) -> 8 | G21: – | H21: 8 | I21: 1 | J21: 1 | K21: =F21 -> 8 | L21: – | M21: =SUM(G21:L21) -> 18 | N21: High | O21: Not Started | P21: Task 11 | Q21: Form, Auto-gen Ref No. (LST-YYYYMMDD-XXXXX), Email/SMS Notify
A22: 14 | B22: Development | C22: Module: Found Report + RFID Integration | D22: 46258 | E22: 46269 | F22: =NETWORKDAYS(D22,E22) -> 10 | G22: – | H22: 10 | I22: 1 | J22: 1 | K22: =F22 -> 10 | L22: – | M22: =SUM(G22:L22) -> 22 | N22: Critical | O22: Not Started | P22: Task 11 | Q22: RFID Scan API, Image Upload ≤8 รูป, E-Signature, Found Form PDF
A23: 15 | B23: Development | C23: Module: Search & Match (Rule-based Scoring) | D23: 46272 | E23: 46290 | F23: =NETWORKDAYS(D23,E23) -> 15 | G23: – | H23: 15 | I23: 1 | J23: 1 | K23: =F23 -> 15 | L23: – | M23: =SUM(G23:L23) -> 32 | N23: Critical | O23: Not Started | P23: Task 13,14 | Q23: Scoring 6 Fields, Auto-suggest ≥70%, Manual Match, RFID Scan Search
A24: 16 | B24: Development | C24: Module: Property Management + Status Flow | D24: 46293 | E24: 46297 | F24: =NETWORKDAYS(D24,E24) -> 5 | G24: – | H24: 5 | I24: 1 | J24: 1 | K24: =F24 -> 5 | L24: – | M24: =SUM(G24:L24) -> 12 | N24: High | O24: Not Started | P24: Task 14 | Q24: 7-Step Status, Expiry Alert, Return Form, Handover Sign
A25: 17 | B25: Development | C25: Module: Report & Statistics + Export | D25: 46300 | E25: 46311 | F25: =NETWORKDAYS(D25,E25) -> 10 | G25: – | H25: 10 | I25: 1 | J25: 1 | K25: =F25 -> 10 | L25: – | M25: =SUM(G25:L25) -> 22 | N25: High | O25: Not Started | P25: Task 13-16 | Q25: Daily/Monthly/Yearly, Export Excel/PDF, User Activity Log
A26: 18 | B26: Development | C26: Module: Admin + Master Data + CRUD + RBAC | D26: 46314 | E26: 46339 | F26: =NETWORKDAYS(D26,E26) -> 20 | G26: – | H26: 20 | I26: 1 | J26: 1 | K26: =F26 -> 20 | L26: – | M26: =SUM(G26:L26) -> 42 | N26: High | O26: Not Started | P26: Task 11 | Q26: User/Role/Permission รายบุคคล+รายกลุ่ม, Session Timeout, RFID Config
A27: 19 | B27: Development | C27: Dashboard & Analytics (Hotspot Heatmap) | D27: 46342 | E27: 46351 | F27: =NETWORKDAYS(D27,E27) -> 8 | G27: – | H27: 8 | I27: 1 | J27: 1 | K27: =F27 -> 8 | L27: – | M27: =SUM(G27:L27) -> 18 | N27: Medium | O27: Not Started | P27: Task 17 | Q27: Match Rate KPI, Peak Hour Chart, Area Hotspot, Trend Graph
A28: TESTING | F28: =SUM(F29:F31) -> 69 | G28: =SUM(G29:G31) -> 0 | H28: =SUM(H29:H31) -> 69 | I28: =SUM(I29:I31) -> 69 | J28: =SUM(J29:J31) -> 0 | K28: =SUM(K29:K31) -> 83 | L28: =SUM(L29:L31) -> 69 | M28: =SUM(M29:M31) -> 290
A29: 21 | B29: Testing | C29: Unit Test | D29: 46340 | E29: 46351 | F29: =NETWORKDAYS(D29,E29) -> 8 | G29: – | H29: =F29 -> 8 | I29: =F29 -> 8 | J29: – | K29: 11 | L29: =F29 -> 8 | M29: =SUM(G29:L29) -> 35 | N29: High | O29: Not Started | P29: Task 13-19 | Q29: Dev เขียน Unit Test, QA Review, Peer Code Review
A30: 22 | B30: Testing | C30: Integration Test (API + RFID End-to-End) | D30: 46270 | E30: 46351 | F30: =NETWORKDAYS(D30,E30) -> 58 | G30: – | H30: =F30 -> 58 | I30: =F30 -> 58 | J30: – | K30: 61 | L30: =F30 -> 58 | M30: =SUM(G30:L30) -> 235 | N30: High | O30: Not Started | P30: Task 21 | Q30: ทดสอบ RFID Reader จริง, E2E Flow ทุก Scenario
A31: 23 | B31: Testing | C31: Performance & Security Test | D31: 46352 | E31: 46356 | F31: =NETWORKDAYS(D31,E31) -> 3 | G31: – | H31: =F31 -> 3 | I31: =F31 -> 3 | J31: – | K31: 11 | L31: =F31 -> 3 | M31: =SUM(G31:L31) -> 20 | N31: High | O31: Not Started | P31: Task 22 | Q31: Load Test, SQL Injection, Session Timeout, HTTPS/SSL
A32: UAT | F32: =SUM(F33:F36) -> 9 | G32: =SUM(G33:G36) -> 4 | H32: =SUM(H33:H36) -> 9 | I32: =SUM(I33:I36) -> 9 | J32: =SUM(J33:J36) -> 2 | K32: =SUM(K33:K36) -> 5 | L32: =SUM(L33:L36) -> 7 | M32: =SUM(M33:M36) -> 36
A33: 25 | B33: UAT | C33: จัดทำ UAT Test Case + Scenario | D33: 46357 | E33: 46359 | F33: =NETWORKDAYS(D33,E33) -> 3 | G33: 1 | H33: 3 | I33: 3 | J33: 1 | K33: – | L33: 2 | M33: =SUM(G33:L33) -> 10 | N33: High | O33: Not Started | P33: Task 23 | Q33: Happy Path + Edge Case + Negative Test ครอบคลุมทุก Module
A34: 26 | B34: UAT | C34: UAT กับเจ้าหน้าที่ CNI (L&F Officer, Supervisor, Admin) | D34: 46360 | E34: 46360 | F34: =NETWORKDAYS(D34,E34) -> 1 | G34: 1 | H34: 1 | I34: 1 | J34: 1 | K34: 1 | L34: 1 | M34: =SUM(G34:L34) -> 6 | N34: Critical | O34: Not Started | P34: Task 24,25 | Q34: ทดสอบจริงกับ User ทุก Role บน Staging Environment
A35: 27 | B35: UAT | C35: Bug Fix + Regression Test | D35: 46364 | E35: 46367 | F35: =NETWORKDAYS(D35,E35) -> 4 | G35: 1 | H35: 4 | I35: 4 | J35: – | K35: 4 | L35: 4 | M35: =SUM(G35:L35) -> 17 | N35: High | O35: Not Started | P35: Task 26 | Q35: แก้ไข Bug ทั้งหมดจาก UAT และทดสอบซ้ำ
A36: 28 | B36: UAT | C36: UAT Sign-off | D36: 46370 | E36: 46370 | F36: =NETWORKDAYS(D36,E36) -> 1 | G36: 1 | H36: 1 | I36: 1 | J36: – | K36: – | L36: – | M36: =SUM(G36:L36) -> 3 | N36: Critical | O36: Not Started | P36: Task 27 | Q36: CNI ลงนาม Acceptance Form — เงื่อนไขก่อน Deploy Production
A37: GO-LIVE | F37: =SUM(F38:F43) -> 30 | G37: =SUM(G38:G43) -> 14 | H37: =SUM(H38:H43) -> 28 | I37: =SUM(I38:I43) -> 27 | J37: =SUM(J38:J43) -> 12 | K37: =SUM(K38:K43) -> 13 | L37: =SUM(L38:L43) -> 13 | M37: =SUM(M38:M43) -> 107
A38: 30 | B38: Go-Live | C38: จัดทำ User Manual ภาษาไทย (ทุก Role) | D38: 46371 | E38: 46374 | F38: =NETWORKDAYS(D38,E38) -> 4 | G38: 1 | H38: 4 | I38: 4 | J38: 1 | K38: – | L38: – | M38: =SUM(G38:L38) -> 10 | N38: High | O38: Not Started | P38: Task 23 | Q38: BA+SA เขียน Manual, UX/UI ทำ Screenshot+Diagram ประกอบ
A39: 31 | B39: Go-Live | C39: ส่งแผนการอบรม และแก้ไขหลังจากพิจารณา | D39: 46377 | E39: 46391 | F39: =NETWORKDAYS(D39,E39) -> 11 | G39: 1 | H39: 11 | I39: 11 | J39: 11 | K39: – | L39: – | M39: =SUM(G39:L39) -> 34
A40: 32 | B40: Go-Live | C40: บันทึก Video การอบรมการใช้งานระบบ | D40: 46391 | E40: 46391 | F40: =NETWORKDAYS(D40,E40) -> 1 | G40: – | H40: 1 | I40: – | J40: – | K40: – | L40: – | M40: =SUM(G40:L40) -> 1 | N40: High | O40: Not Started | P40: Task 29 | Q40: Trainer บันทึก Video ส่งมอบให้ CNI ใช้งานโดยไม่มีค่าใช้จ่าย
A41: 33 | B41: Go-Live | C41: อบรมผู้ใช้งาน (L&F Officer, Supervisor, Admin) | D41: 46392 | E41: 46392 | F41: =NETWORKDAYS(D41,E41) -> 1 | G41: 2 | H41: 2 | I41: 2 | J41: – | K41: – | L41: – | M41: =SUM(G41:L41) -> 6 | N41: High | O41: Not Started | P41: Task 29,30 | Q41: จัดทำรายงานผลการอบรม + ใบลงชื่อ + ภาพถ่ายการอบรม
...

Sheet Deliverables & Milestones
A1: Deliverables & Milestones — CNI Lost & Found System
A3: งวด | B3: Milestone | C3: กำหนดส่ง | D3: Deliverables | E3: ผู้รับผิดชอบ | F3: เงื่อนไขการรับมอบ | G3: สถานะ
A4: 1 | B4: Kick-Off Complete | C4: ='Detailed Task Plan'!E6 -> 46178 | D4: 1. รายงาน Kick-Off Meeting 2. Project Plan (Approved) 3. Project Charter | E4: PM | F4: CNI ลงนามรับทราบ Project Plan และ Timeline | G4: Not Started
A5: 2 | B5: Requirement & Design Sign-off | C5: ='Gantt Chart'!E16 -> 46234 | D5: 1. Business Requirements Document (BRD) 2. System Requirements Spec (SRS) 3. Use Case + ER Diagram + DFD 4. Wireframe / Hi-fi Mockup (Figma) 5. Design System Guide | E5: BA, SA, UX/UI, PM | F5: CNI Committee ลงนาม Sign-off ครบทั้ง BRD + Mockup | G5: Not Started
A6: 3 | B6: Development & Testing Complete | C6: ='Detailed Task Plan'!E31 -> 46356 | D6: 1. Source Code ระบบครบทุก Module 2. Unit Test Report 3. Integration Test Report (RFID E2E) 4. Performance & Security Test Report | E6: Dev, QA, SA | F6: ผ่านเกณฑ์ Test Coverage ≥80% และ Performance Test | G6: Not Started
A7: 4 | B7: UAT Sign-off | C7: ='Detailed Task Plan'!E36 -> 46370 | D7: 1. Usability Test Report 2. UAT Test Result Report 3. Bug Fix Report 4. ระบบ Staging พร้อม Deploy Production | E7: QA, SA, BA, UX/UI, PM | F7: CNI ลงนาม UAT Acceptance Form | G7: Not Started
A8: 5 | B8: Go-Live | C8: ='Gantt Chart'!E42 -> 46409 | D8: 1. ระบบ Production พร้อมใช้งาน (Uptime ≥99%) 2. User Manual ภาษาไทย (ทุก Role) 3. Video การอบรม 4. รายงานผลการอบรม + ใบลงชื่อ 5. Support Plan 2 สัปดาห์ | E8: PM, Dev, BA, SA | F8: ระบบ Stable 2 สัปดาห์แรก, CNI ยืนยันการรับมอบ | G8: Not Started

Sheet Risk Register
A1: Risk Register — CNI Lost & Found System
A3: # | B3: ความเสี่ยง | C3: Phase | D3: โอกาส | E3: ผลกระทบ | F3: Risk Level | G3: แผนรับมือ | H3: เจ้าของ | I3: สถานะ
A4: 1 | B4: CNI ไม่ Sign-off Requirement ตามกำหนด ทำให้ Dev ล่าช้า | C4: Req | D4: สูง | E4: สูง | F4: HIGH | G4: กำหนด Hard Deadline ใน Contract, Escalate ทันทีถ้าเกิน 3 WD | H4: PM | I4: Open
A5: 2 | B5: RFID Reader ไม่ Compatible กับ Network CNI ทำให้ Dev ล่าช้า | C5: Dev | D5: ปานกลาง | E5: สูง | F5: HIGH | G5: ทดสอบ RFID ใน Sprint แรก, เตรียม Fallback เป็น QR Code | H5: HW, Dev | I5: Open
A6: 3 | B6: Scope Creep CNI เพิ่ม Feature ระหว่าง Dev ทำให้ต้อง Dev เพิ่มจากแผนแรก | C6: Dev | D6: สูง | E6: ปานกลาง | F6: HIGH | G6: Freeze Req หลัง Sign-off เสมอแต่เมื่อเกิดเคสนี้จริงๆ ทางทีมต้อง Brain Storm กันก่อนว่าในเคสนี้ เป็นสิ่งที่ทางทีมคิดให้ลูกค้าไม่ครบ หรือ Scope Creep จริงๆ หากเป็น New Feature ให้ทาง Dev/PM ประเมิน Manday และนำไปขอตกลงกับลูกค้าเพื่อเพิ่มระยะเวลา แต่หากเป็น Chang Request ให้ทาง BA จัดทำเอกสารการขอเปลี่ยนแปลงและให้ Dev/PM ประเมิน Manday และนำไปคิดเงินลูกค้าเพิ่ม และขยายระยะเวลา | H6: PM, BA, Dev | I6: Open
A7: 4 | B7: Dev Resource ไม่เพียงพอ / ลาออกกลางโปรเจกต์ | C7: Dev | D7: ปานกลาง | E7: สูง | F7: HIGH | G7: Buffer 10% ใน Plan, Backup Dev 1 คน, Document ทุก Sprint | H7: PM | I7: Open
A8: 5 | B8: UI ที่ Dev Build ไม่ตรง Mockup | C8: Dev | D8: สูง | E8: ปานกลาง | F8: HIGH | G8: Figma Handoff ชัดเจน, UX/UI Review ทุก Sprint ก่อน Dev | H8: UX/UI, Dev | I8: Open
A9: 7 | B9: Bug Critical ระหว่าง UAT ทำให้ Go-Live ล่าช้า | C9: UAT | D9: ปานกลาง | E9: สูง | F9: HIGH | G9: Integration Test ครบก่อน UAT, Buffer Bug Fix 4 WD ใน Plan | H9: Dev, QA | I9: Open
A10: 8 | B10: ระบบ Production Server ไม่ตรง Spec | C10: Go-Live | D10: ต่ำ | E10: สูง | F10: MEDIUM | G10: ระบุ Server Spec ชัดเจนใน TOR, ตรวจสอบก่อน Deploy | H10: Dev, CNI IT | I10: Open
A11: 9 | B11: Usability ต่ำ — เจ้าหน้าที่ใช้ระบบจริงไม่ได้ | C11: UAT | D11: ปานกลาง | E11: สูง | F11: HIGH | G11: BA+UX/UI นำเสนอ Prototype ก่อน Dev และ Sign Off แล้ว หากในการทำงานจริงไม่สามารถใข้งานได้ ต้องการปรับตาม Feedback แต่ต้องไม่เกิน Scope PMจะต้องขอขยายไทม์ไลน์จากแผนเดิม เพื่อให้ทีมแก้ไข interface | H11: PM, BA, UX/UI | I11: Open
